Workbook

Sheet 00_Histori
B2: REVISION HISTORY
B4: No | C4: Tanggal (dd-mm-yyyy) | D4: Oleh (init) | E4: Deskripsi Perubahan
B5: 1 | C5: 46167 | D5: Claude | E5: Template KKF Proyek Investasi 1-Tahun dibuat sebagai pendamping KKF Proyek Investasi multi-year. Struktur: monthly cashflow + XIRR (annualized). Sudah include fix dari audit: PPN 12%, BCR check di conclusion, CAPEX D19 include semua section, working capital int yg di-link.

Sheet 01_Menu
B2: KKF PROYEK INVESTASI 1-TAHUN
B3: Kajian Kelayakan Finansial untuk kontrak Connectivity short-term (≤ 12 bulan) — basis XIRR bulanan
B4: ⚠️ TEMPLATE BERISI SAMPLE DATA (CAPEX 21M, Sewa 5M, OTC 1.5M, OPEX 30%) — GANTI DENGAN DATA AKTUAL PROYEK ANDA
B5: A. IDENTITAS PROYEK (input)
B6: Nama Project | C6: (Isi nama proyek) | D6: Sama dengan SP2K / SPH
B7: Nama Pelanggan | C7: (Isi nama pelanggan) | D7: Match dengan NPWP
B8: Nomor Kontrak / BAKBB | D8: Jika sudah ada
B9: Tanggal Mulai Layanan | C9: 46174 | D9: dd-mmm-yyyy
B10: Durasi Kontrak (bulan) | C10: 12 | D10: Max 12 untuk template ini
B11: Tanggal Akhir Layanan | C11: =EDATE(C9,C10) -> 46539 | D11: Auto dari Start + Durasi
B12: PIC Sales | C12: (Nama Sales)
B13: PIC Solution Architect | C13: Solar
B14: Bidang / Manager | C14: (Nama Manager)
B15: GM / SRM | C15: (Nama GM)
C16: (Nama GM)
B17: B. URUTAN PENGISIAN (klik link untuk navigasi)
B18: Step 1 | C18: Isi RAB Lastmile (8 item std) | D18: → Buka 02_Inv_Details
B19: Step 2 | C19: Mapping CAPEX (kategori standar) | D19: → Buka 03_CAPEX
B20: Step 3 | C20: Isi OPEX Bulanan (12 kolom) | D20: → Buka 04_OPEX_Bulanan
B21: Step 4 | C21: Isi Pendapatan (sewa per bulan + OTC) | D21: → Buka 05_Pendapatan
B22: Step 5 | C22: Review Asumsi (PPN, WACC, kurs) | D22: → Buka 06_Asumsi
B23: Step 6 | C23: Cek Cashflow Bulanan & Decision Metrics | D23: → Buka 07_Cashflow_Bulanan
B24: Step 7 | C24: Generate Executive Summary untuk Approval | D24: → Buka 08_Ex_Summary
B26: C. DASHBOARD KELAYAKAN (output otomatis)
B27: • | C27: ='03_CAPEX'!D20 -> 75000000 | E27: Investasi awal (Month 0)
B28: • | C28: ='05_Pendapatan'!I20 -> 5000000 | E28: Pendapatan one-time charge
B29: • | C29: ='05_Pendapatan'!J20 -> 8900000 | E29: Total sewa bulanan dari pelanggan
B30: • | C30: =AVERAGE('04_OPEX_Bulanan'!F15:Q15) -> 2673016.8 | E30: Rata-rata OPEX 12 bulan
B31: • | C31: ='07_Cashflow_Bulanan'!S14 -> 5000000 | E31: Sewa + OTC selama kontrak
B32: • | C32: ='07_Cashflow_Bulanan'!S19 -> 75000000 | E32: Total OPEX selama kontrak
B33: • | C33: ='07_Cashflow_Bulanan'!S22-(-'07_Cashflow_Bulanan'!F22) -> -70276201 | E33: Sum inflow operasi minus CAPEX
B35: D. KPI KELAYAKAN (vs threshold)
C36: Metric | D36: Nilai | E36: Satuan | F36: Threshold | H36: Status | I36: Keterangan
C37: NPV (Net Present Value) | D37: ='07_Cashflow_Bulanan'!N27 -> 1044579.8 | E37: Rp | F37: > 0 | H37: =IF(ISNUMBER(D37),IF(D37>0,"LAYAK","TIDAK LAYAK"),"—") -> LAYAK | I37: NPV positif = proyek menambah nilai
C38: XIRR (Annualized IRR) | D38: ='07_Cashflow_Bulanan'!N28 -> 0.12773048 | E38: % p.a. | F38: > WACC | H38: =IF(ISNUMBER(D38),IF(D38>'06_Asumsi'!D5,"LAYAK","TIDAK LAYAK"),"—") -> LAYAK | I38: XIRR > WACC = above cost of capital
C39: BCR / PI (Profitability Index) | D39: ='07_Cashflow_Bulanan'!N29 -> 1.4316323 | E39: x | F39: ≥ 1.08 | H39: =IF(ISNUMBER(D39),IF(D39>='06_Asumsi'!D8,"LAYAK",IF(D39>='06_Asumsi'!D7,"BUTUH JUSTIFIKASI","TIDAK LAYAK")),"—") -> LAYAK | I39: Threshold per Memo DirKeu 16/09/2025: Min 1.08, Mandatory 1.23
C40: Payback Period | D40: ='07_Cashflow_Bulanan'!N30 -> 0 | E40: bulan | F40: < durasi | H40: =IF(ISNUMBER(D40),IF(AND(D40>0,D40<C10),"LAYAK","WASPADA"),"—") -> WASPADA | I40: Balik modal harus < durasi kontrak
C41: Simple ROI (kontrak) | D41: ='07_Cashflow_Bulanan'!N31 -> 1.062984 | E41: % | F41: > 0% | H41: =IF(ISNUMBER(D41),IF(D41>0,"PROFIT","RUGI"),"—") -> PROFIT | I41: Total Net Inflow / CAPEX selama durasi
B43: E. KESIMPULAN OTOMATIS
B44: =IF(AND(D37>0,D38>'06_Asumsi'!D5,D39>='06_Asumsi'!D8,D40<C10),"✓ INVESTASI LAYAK — Semua kriteria (NPV>0, XIRR>WACC, BCR≥1.23 Mandatory, Payback<durasi) terpenuhi. Lanjutkan ke approval.",IF(AND(D37>0,D38>'06_Asumsi'!D5,D39>='06_Asumsi'!D7),"⚠ INVESTASI LAYAK DENGAN CATATAN — BCR antara Min (1.08) dan Mandatory (1.23). Lampirkan form justifikasi approval per Memo DirKeu 16/09/2025.",IF(AND(D37>0,D38>'06_Asumsi'!D5,D39>1),"⚠ MARGINAL — BCR < 1.08. Butuh persetujuan Direksi terkait sebelum dilanjutkan.","✗ TIDAK LAYAK — Salah satu kriteria utama tidak terpenuhi. Revisi pricing/asumsi atau tolak proyek."))) -> ✓ INVESTASI LAYAK — Semua kriteria (NPV>0, XIRR>WACC, BCR≥1.23 Mandatory, Payback<durasi) terpenuhi. Lanjutkan ke approval.
...

Sheet 02_Inv_Details
B2: 02 — RAB LASTMILE (Detail Investasi)
B3: Isi kolom D (Jumlah IDR) sesuai survey lapangan. Sel putih = input. Sel biru = auto-calculate.
B5: ← Kembali ke Menu | E5: Nama Project: | F5: ='01_Menu'!C7 -> (Isi nama pelanggan)
B7: No | C7: Items | D7: Jumlah (IDR) | F7: Catatan / Source
B8: 1 | C8: Fiber Optic Cable (FOC) Lastmile | D8: 50000000 | F8: Per meter × panjang lastmile (dari Calc RAB)
B9: 2 | C9: Fiber Optic Terminal (FOT) Lastmile | D9: 5000000 | F9: ODF / Joint Box / Pigtail
B10: 3 | C10: Biaya perizinan (apabila ada) | D10: 20000000 | F10: Sitac / RT-RW / KAK / dll
B11: 4 | C11: Biaya Interkoneksi ke Jaringan pihak ketiga | D11: 0 | F11: Jika cross network
B12: 5 | C12: Biaya collocation perangkat | D12: 0 | F12: Sewa rack/space di lokasi pihak ke-3
B13: 6 | C13: Biaya tracing core | D13: 0 | F13: Jika utilisasi core existing
B14: 7 | C14: Biaya peningkatan kapasitas POP | D14: 0 | F14: Upgrade switch/router POP jika diperlukan
B15: 8 | C15: Sarana Penunjang | D15: 0 | F15: Kabel patch, label, accessories, dll
C16: TOTAL RAB LASTMILE | D16: =SUM(D8:D15) -> 75000000
B18: Catatan Khusus:
B19: 1. Khusus untuk Rekonstruksi: WAJIB lampirkan evidence Realisasi SAP
B20: 2. Pricing material → mengacu Harga SAP terkini (cek tanggal update di Calc RAB)
B21: 3. Pricing jasa → mengacu KHS Amandemen 2024 (atau terbaru jika sudah ada)
B22: 4. Jika RAB diisi dari Calc RAB Akv SBU: gunakan output INPUT!C42 sebagai referensi

Sheet 03_CAPEX
B2: 03 — TOTAL CAPITAL EXPENDITURE (CAPEX)
B3: Mapping investasi ke kategori standar. Sub-kategori 1.b auto-link dari 02_Inv_Details.
B5: ← Kembali ke Menu
B7: No | C7: Items | D7: Jumlah (IDR) | F7: Catatan
B8: 1. | C8: CAPEX | D8: =D9+D10+D11+D15 -> 75000000
B9: a | C9: Jaringan Kabel Optik | D9: 0 | F9: Aerial / Underground
B10: b | C10: Perangkat Telekomunikasi | D10: ='02_Inv_Details'!D16 -> 75000000 | F10: Auto dari 02_Inv_Details total
B11: c | C11: Peralatan Teknologi Informasi (sub-total) | D11: =D12+D13+D14 -> 0 | F11: Auto sum 3 sub items
C12: - Perangkat Keras/Hardware | D12: 0
C13: - Piranti Lunak/Software | D13: 0
C14: - Lisensi | D14: 0
B15: d | C15: Lainnya (CAPEX) | D15: 0
B17: 2. | C17: Project Management and Implementation | D17: 0 | F17: PIC/PMO cost
B18: 3. | C18: Biaya Investasi Lainnya | D18: 0 | F18: Contingency, training, dll
C20: TOTAL BIAYA INVESTASI (CAPEX) | D20: =D8+D17+D18 -> 75000000 | F20: ✓ Sudah include Section 1, 2, 3 (fix dari template multi-year)

Sheet 04_OPEX_Bulanan
B2: 04 — OPEX / O&M BULANAN (12 Bulan)
B3: Isi koefisien (kolom D) atau langsung baseline (kolom E). Bulan 1-12 auto-calculate dengan inflasi bulanan kompound.
B5: ← Kembali ke Menu | E5: Pendapatan/bulan (auto): | F5: ='05_Pendapatan'!J20 -> 8900000 | H5: Inflasi bulanan: | I5: =(1+'06_Asumsi'!D11)^(1/12)-1 -> 0.00020529053
B7: No | C7: Komponen Biaya | D7: Koef (%) | E7: Baseline/bulan (Rp) | F7: Bulan 1 | G7: Bulan 2 | H7: Bulan 3 | I7: Bulan 4 | J7: Bulan 5 | K7: Bulan 6 | L7: Bulan 7 | M7: Bulan 8 | N7: Bulan 9 | O7: Bulan 10 | P7: Bulan 11 | Q7: Bulan 12
B8: 1 | C8: Overhead (% dari Pendapatan) | D8: 0.25 | E8: =D8*$F$5 -> 2225000 | F8: =$E8*(1+$I$5)^(1-1) -> 2225000 | G8: =$E8*(1+$I$5)^(2-1) -> 2225456.8 | H8: =$E8*(1+$I$5)^(3-1) -> 2225913.6 | I8: =$E8*(1+$I$5)^(4-1) -> 2226370.6 | J8: =$E8*(1+$I$5)^(5-1) -> 2226827.6 | K8: =$E8*(1+$I$5)^(6-1) -> 2227284.8 | L8: =$E8*(1+$I$5)^(7-1) -> 2227742 | M8: =$E8*(1+$I$5)^(8-1) -> 2228199.4 | N8: =$E8*(1+$I$5)^(9-1) -> 2228656.8 | O8: =$E8*(1+$I$5)^(10-1) -> 2229114.3 | P8: =$E8*(1+$I$5)^(11-1) -> 2229571.9 | Q8: =$E8*(1+$I$5)^(12-1) -> 2230029.6
B9: 2 | C9: Pemeliharaan rutin | D9: 0.05 | E9: =D9*$F$5 -> 445000 | F9: =$E9*(1+$I$5)^(1-1) -> 445000 | G9: =$E9*(1+$I$5)^(2-1) -> 445091.35 | H9: =$E9*(1+$I$5)^(3-1) -> 445182.73 | I9: =$E9*(1+$I$5)^(4-1) -> 445274.12 | J9: =$E9*(1+$I$5)^(5-1) -> 445365.53 | K9: =$E9*(1+$I$5)^(6-1) -> 445456.96 | L9: =$E9*(1+$I$5)^(7-1) -> 445548.41 | M9: =$E9*(1+$I$5)^(8-1) -> 445639.87 | N9: =$E9*(1+$I$5)^(9-1) -> 445731.36 | O9: =$E9*(1+$I$5)^(10-1) -> 445822.86 | P9: =$E9*(1+$I$5)^(11-1) -> 445914.39 | Q9: =$E9*(1+$I$5)^(12-1) -> 446005.93
B10: 3 | C10: Sewa Backbone / Transmissi | D10: 0 | E10: =D10*$F$5 -> 0 | F10: =$E10*(1+$I$5)^(1-1) -> 0 | G10: =$E10*(1+$I$5)^(2-1) -> 0 | H10: =$E10*(1+$I$5)^(3-1) -> 0 | I10: =$E10*(1+$I$5)^(4-1) -> 0 | J10: =$E10*(1+$I$5)^(5-1) -> 0 | K10: =$E10*(1+$I$5)^(6-1) -> 0 | L10: =$E10*(1+$I$5)^(7-1) -> 0 | M10: =$E10*(1+$I$5)^(8-1) -> 0 | N10: =$E10*(1+$I$5)^(9-1) -> 0 | O10: =$E10*(1+$I$5)^(10-1) -> 0 | P10: =$E10*(1+$I$5)^(11-1) -> 0 | Q10: =$E10*(1+$I$5)^(12-1) -> 0
B11: 4 | C11: Pulsa data SIM management | D11: 0 | E11: =D11*$F$5 -> 0 | F11: =$E11*(1+$I$5)^(1-1) -> 0 | G11: =$E11*(1+$I$5)^(2-1) -> 0 | H11: =$E11*(1+$I$5)^(3-1) -> 0 | I11: =$E11*(1+$I$5)^(4-1) -> 0 | J11: =$E11*(1+$I$5)^(5-1) -> 0 | K11: =$E11*(1+$I$5)^(6-1) -> 0 | L11: =$E11*(1+$I$5)^(7-1) -> 0 | M11: =$E11*(1+$I$5)^(8-1) -> 0 | N11: =$E11*(1+$I$5)^(9-1) -> 0 | O11: =$E11*(1+$I$5)^(10-1) -> 0 | P11: =$E11*(1+$I$5)^(11-1) -> 0 | Q11: =$E11*(1+$I$5)^(12-1) -> 0
B12: 5 | C12: Akomodasi tim NOC/Field | D12: 0 | E12: =D12*$F$5 -> 0 | F12: =$E12*(1+$I$5)^(1-1) -> 0 | G12: =$E12*(1+$I$5)^(2-1) -> 0 | H12: =$E12*(1+$I$5)^(3-1) -> 0 | I12: =$E12*(1+$I$5)^(4-1) -> 0 | J12: =$E12*(1+$I$5)^(5-1) -> 0 | K12: =$E12*(1+$I$5)^(6-1) -> 0 | L12: =$E12*(1+$I$5)^(7-1) -> 0 | M12: =$E12*(1+$I$5)^(8-1) -> 0 | N12: =$E12*(1+$I$5)^(9-1) -> 0 | O12: =$E12*(1+$I$5)^(10-1) -> 0 | P12: =$E12*(1+$I$5)^(11-1) -> 0 | Q12: =$E12*(1+$I$5)^(12-1) -> 0
B13: 6 | C13: Lain-lain operasional | D13: 0 | E13: =D13*$F$5 -> 0 | F13: =$E13*(1+$I$5)^(1-1) -> 0 | G13: =$E13*(1+$I$5)^(2-1) -> 0 | H13: =$E13*(1+$I$5)^(3-1) -> 0 | I13: =$E13*(1+$I$5)^(4-1) -> 0 | J13: =$E13*(1+$I$5)^(5-1) -> 0 | K13: =$E13*(1+$I$5)^(6-1) -> 0 | L13: =$E13*(1+$I$5)^(7-1) -> 0 | M13: =$E13*(1+$I$5)^(8-1) -> 0 | N13: =$E13*(1+$I$5)^(9-1) -> 0 | O13: =$E13*(1+$I$5)^(10-1) -> 0 | P13: =$E13*(1+$I$5)^(11-1) -> 0 | Q13: =$E13*(1+$I$5)^(12-1) -> 0
B14: 7 | C14: Lain-lain (2) | D14: 0 | E14: =D14*$F$5 -> 0 | F14: =$E14*(1+$I$5)^(1-1) -> 0 | G14: =$E14*(1+$I$5)^(2-1) -> 0 | H14: =$E14*(1+$I$5)^(3-1) -> 0 | I14: =$E14*(1+$I$5)^(4-1) -> 0 | J14: =$E14*(1+$I$5)^(5-1) -> 0 | K14: =$E14*(1+$I$5)^(6-1) -> 0 | L14: =$E14*(1+$I$5)^(7-1) -> 0 | M14: =$E14*(1+$I$5)^(8-1) -> 0 | N14: =$E14*(1+$I$5)^(9-1) -> 0 | O14: =$E14*(1+$I$5)^(10-1) -> 0 | P14: =$E14*(1+$I$5)^(11-1) -> 0 | Q14: =$E14*(1+$I$5)^(12-1) -> 0
C15: TOTAL OPEX PER BULAN | E15: — | F15: =SUM(F8:F14) -> 2670000 | G15: =SUM(G8:G14) -> 2670548.1 | H15: =SUM(H8:H14) -> 2671096.4 | I15: =SUM(I8:I14) -> 2671644.7 | J15: =SUM(J8:J14) -> 2672193.2 | K15: =SUM(K8:K14) -> 2672741.8 | L15: =SUM(L8:L14) -> 2673290.4 | M15: =SUM(M8:M14) -> 2673839.2 | ... Q15: =SUM(Q8:Q14) -> 2676035.6
B17: Catatan:
B18: 1. Baseline (kolom E) = Koef × Pendapatan/bulan. Bisa di-override manual jika baseline diketahui fixed (mis. sewa).
B19: 2. Inflasi bulanan = (1+inflasi tahunan)^(1/12) - 1. Update inflasi tahunan di sheet 06_Asumsi.
B20: 3. Hanya Bulan 1 sampai dengan durasi kontrak (01_Menu!C11) yang akan masuk ke Cashflow. Bulan setelahnya akan diabaikan otomatis.
B21: 4. Default Overhead 25% mengikuti pendekatan SBU (~24.29% di template multi-year). Sesuaikan jika ada justifikasi.

Sheet 05_Pendapatan
B2: 05 — KOMPOSISI PENDAPATAN
B3: Daftar layanan dijual ke pelanggan dengan harga & qty. OTC = one-time charge (Month 1). Sewa = recurring monthly.
B5: ← Kembali ke Menu
B7: No | C7: Tipe Service | D7: Nama Pelanggan | E7: Lokasi | F7: Harsat (Rp) | G7: Qty | H7: Satuan | I7: OTC (Rp) | J7: Sewa/bulan (Rp)
B8: 1 | C8: Contoh: IBBC CIR4-BW50 On-Net FTTH | D8: PT Contoh Pelanggan (NPWP 99.xxx.xxx.x-xxx.xxx) | E8: Medan Pusat | F8: 8900000 | G8: 1 | H8: unit | I8: 5000000 | J8: =F8*G8 -> 8900000
B9: 2 | F9: 0 | G9: 0 | H9: unit | I9: 0 | J9: =F9*G9 -> 0
B10: 3 | F10: 0 | G10: 0 | H10: unit | I10: 0 | J10: =F10*G10 -> 0
B11: 4 | F11: 0 | G11: 0 | H11: unit | I11: 0 | J11: =F11*G11 -> 0
B12: 5 | F12: 0 | G12: 0 | H12: unit | I12: 0 | J12: =F12*G12 -> 0
B13: 6 | F13: 0 | G13: 0 | H13: unit | I13: 0 | J13: =F13*G13 -> 0
B14: 7 | F14: 0 | G14: 0 | H14: unit | I14: 0 | J14: =F14*G14 -> 0
B15: 8 | F15: 0 | G15: 0 | H15: unit | I15: 0 | J15: =F15*G15 -> 0
B16: 9 | F16: 0 | G16: 0 | H16: unit | I16: 0 | J16: =F16*G16 -> 0
B17: 10 | F17: 0 | G17: 0 | H17: unit | I17: 0 | J17: =F17*G17 -> 0
B18: 11 | F18: 0 | G18: 0 | H18: unit | I18: 0 | J18: =F18*G18 -> 0
B19: 12 | F19: 0 | G19: 0 | H19: unit | I19: 0 | J19: =F19*G19 -> 0
C20: TOTAL | I20: =SUM(I8:I19) -> 5000000 | J20: =SUM(J8:J19) -> 8900000
B22: Catatan & Validasi:
B23: 1. KONSISTENSI WAJIB: nama layanan & qty di sini HARUS = LKPP = iCRM = Surat Penawaran
B24: 2. OTC dibayar di Month 1 (umumnya beriringan dengan instalasi/aktivasi)
B25: 3. Sewa per bulan = recurring revenue (Month 1 sampai durasi kontrak)
B26: 4. Untuk layanan gratis (mis. promo): isi Harsat = 0, OTC = 0, tapi masih perlu di-list untuk traceability

Sheet 06_Asumsi
B2: 06 — ASUMSI FINANSIAL & EKONOMI
B3: Sel kuning = asumsi (perlu update berkala). Cek tanggal terakhir update di kolom 'Source'.
C4: Asumsi | D4: Value | E4: Satuan | F4: Source | G4: Update Terakhir
B5: • | C5: WACC ICON+ (annual) | D5: 0.0972 | E5: % p.a. | F5: Memo VP Keuangan April 2026 | G5: 46113
B6: • | C6: WACC bulanan (auto, compounded) | D6: =(1+D5)^(1/12)-1 -> 0.0077600779 | E6: % p.bln | F6: Auto dari WACC annual (=(1+WACC_yr)^(1/12)-1)
B7: • | C7: BCR/PI Minimum | D7: 1.08 | E7: x | F7: Memo DirKeu 16 Sept 2025 | G7: 45916
B8: • | C8: BCR/PI Mandatory | D8: 1.23 | E8: x | F8: Memo DirKeu 16 Sept 2025 | G8: 45916
B9: • | C9: Inflasi Rupiah (annual) | D9: 0.03 | E9: % p.a. | F9: Bank Dunia / BI Forecast | G9: 46023
B10: • | C10: Kurs USD/IDR | D10: 16500 | E10: Rp/USD | F10: BI Tengah (cek terkini) | G10: 46167
B11: • | C11: Inflasi bulanan (auto) | D11: =(1+D9)^(1/12)-1 -> 0.0024662698 | E11: % p.bln | F11: Auto dari Inflasi annual
B12: • | C12: PPN | D12: 0.12 | E12: % | F12: UU HPP 2022 (efektif 2025+) | G12: 45658
B13: • | C13: PPh Badan | D13: 0.22 | E13: % | F13: UU PPh | G13: 44562
B14: • | C14: PPh Pasal 23 Jasa | D14: 0.02 | E14: % | F14: PPh23 = 15% × 30% | G14: 44562
B15: • | C15: Umur Piutang (AR) | D15: 70 | E15: hari | F15: Practice ICON+ | G15: 45292
B16: • | C16: Umur Hutang (AP) | D16: 40 | E16: hari | F16: Practice ICON+ | G16: 45292
B17: • | C17: Suku Bunga Modal Kerja (annual) | D17: 0.094 | E17: % p.a. | F17: Bank Persero Nasional (BPS) | G17: 46143
B19: Catatan Verifikator:
B20: 1. ⚠️ WAJIB UPDATE BULANAN: WACC (D5) — minta dari VP Keuangan setiap awal bulan
B21: 2. ⚠️ Kurs USD (D10) — verifikasi pada hari verifikasi jika ada komponen USD
B22: 3. ⚠️ PPN 12% berlaku sejak 1 Jan 2025. Jangan ubah kembali ke 10%
B23: 4. BCR Min 1.08 & Mandatory 1.23 — jangan diubah tanpa Memo DirKeu baru
B24: 5. Inflasi bulanan (D11) → dipakai di sheet 04_OPEX_Bulanan untuk kompound bulan-bulanan

Sheet 07_Cashflow_Bulanan
B2: 07 — CASHFLOW BULANAN & DECISION METRICS
B3: Sheet kalkulasi inti: XIRR (annualized), NPV, BCR, Payback. Hanya bulan 1 sd durasi kontrak yang berkontribusi ke cashflow.
B5: ← Kembali ke Menu | E5: Durasi kontrak: | F5: ='01_Menu'!C10 -> 12 | H5: WACC bulanan: | I5: ='06_Asumsi'!D6 -> 0.0077600779 | K5: WACC annual: | L5: ='06_Asumsi'!D5 -> 0.0972
C8: Komponen Cashflow | E8: Cell ref | F8: Month 0 | G8: Month 1 | H8: Month 2 | I8: Month 3 | J8: Month 4 | K8: Month 5 | L8: Month 6 | M8: Month 7 | N8: Month 8 | O8: Month 9 | P8: Month 10 | Q8: Month 11 | R8: Total | S8: Total
C9: Tanggal | F9: ='01_Menu'!C9 -> 46174 | G9: =EDATE($F$9,1) -> 46204 | H9: =EDATE($F$9,2) -> 46235 | I9: =EDATE($F$9,3) -> 46266 | J9: =EDATE($F$9,4) -> 46296 | K9: =EDATE($F$9,5) -> 46327 | L9: =EDATE($F$9,6) -> 46357 | M9: =EDATE($F$9,7) -> 46388 | N9: =EDATE($F$9,8) -> 46419 | O9: =EDATE($F$9,9) -> 46447 | P9: =EDATE($F$9,10) -> 46478 | Q9: =EDATE($F$9,11) -> 46508 | R9: =EDATE($F$9,12) -> 46539
C10: Aktif? (1 = ya) | F10: =1 -> 1 | G10: =IF(1<=$F$5,1,0) -> 1 | H10: =IF(2<=$F$5,1,0) -> 1 | I10: =IF(3<=$F$5,1,0) -> 1 | J10: =IF(4<=$F$5,1,0) -> 1 | K10: =IF(5<=$F$5,1,0) -> 1 | L10: =IF(6<=$F$5,1,0) -> 1 | M10: =IF(7<=$F$5,1,0) -> 1 | N10: =IF(8<=$F$5,1,0) -> 1 | O10: =IF(9<=$F$5,1,0) -> 1 | P10: =IF(10<=$F$5,1,0) -> 1 | Q10: =IF(11<=$F$5,1,0) -> 1 | R10: =IF(12<=$F$5,1,0) -> 1
C12: INFLOW (kas masuk)
C13: Sewa per bulan | E13: 05_Pdpt!J20 | F13: =0 -> 0 | G13: =G10*'05_Pendapatan'!$J$20 -> 8900000 | H13: =H10*'05_Pendapatan'!$J$20 -> 8900000 | I13: =I10*'05_Pendapatan'!$J$20 -> 8900000 | J13: =J10*'05_Pendapatan'!$J$20 -> 8900000 | K13: =K10*'05_Pendapatan'!$J$20 -> 8900000 | L13: =L10*'05_Pendapatan'!$J$20 -> 8900000 | M13: =M10*'05_Pendapatan'!$J$20 -> 8900000 | N13: =N10*'05_Pendapatan'!$J$20 -> 8900000 | ... R13: =R10*'05_Pendapatan'!$J$20 -> 8900000 | S13: =SUM(F13:R13) -> 106800000
C14: OTC (one-time, Month 1) | E14: 05_Pdpt!I20 | F14: =0 -> 0 | G14: =G10*'05_Pendapatan'!$I$20 -> 5000000 | H14: =0 -> 0 | I14: =0 -> 0 | J14: =0 -> 0 | K14: =0 -> 0 | L14: =0 -> 0 | M14: =0 -> 0 | N14: =0 -> 0 | O14: =0 -> 0 | ... R14: =0 -> 0 | S14: =SUM(F14:R14) -> 5000000
C15: Total Inflow | F15: =F13+F14 -> 0 | G15: =G13+G14 -> 13900000 | H15: =H13+H14 -> 8900000 | I15: =I13+I14 -> 8900000 | J15: =J13+J14 -> 8900000 | K15: =K13+K14 -> 8900000 | L15: =L13+L14 -> 8900000 | M15: =M13+M14 -> 8900000 | ... R15: =R13+R14 -> 8900000 | S15: =SUM(F15:R15) -> 111800000
C17: OUTFLOW (kas keluar)
C18: OPEX Bulanan | E18: 04_OPEX!F15:Q15 | F18: =0 -> 0 | G18: =G10*'04_OPEX_Bulanan'!F$15 -> 2670000 | H18: =H10*'04_OPEX_Bulanan'!G$15 -> 2670548.1 | I18: =I10*'04_OPEX_Bulanan'!H$15 -> 2671096.4 | J18: =J10*'04_OPEX_Bulanan'!I$15 -> 2671644.7 | K18: =K10*'04_OPEX_Bulanan'!J$15 -> 2672193.2 | L18: =L10*'04_OPEX_Bulanan'!K$15 -> 2672741.8 | M18: =M10*'04_OPEX_Bulanan'!L$15 -> 2673290.4 | N18: =N10*'04_OPEX_Bulanan'!M$15 -> 2673839.2 | ... R18: =R10*'04_OPEX_Bulanan'!Q$15 -> 2676035.6 | S18: =SUM(F18:R18) -> 32076201
C19: CAPEX (investasi, Month 0) | E19: 03_CAPEX!D20 | F19: ='03_CAPEX'!$D$20 -> 75000000 | G19: =0 -> 0 | H19: =0 -> 0 | I19: =0 -> 0 | J19: =0 -> 0 | K19: =0 -> 0 | L19: =0 -> 0 | M19: =0 -> 0 | N19: =0 -> 0 | ... R19: =0 -> 0 | S19: =SUM(F19:R19) -> 75000000
C20: Total Outflow | F20: =F18+F19 -> 75000000 | G20: =G18+G19 -> 2670000 | H20: =H18+H19 -> 2670548.1 | I20: =I18+I19 -> 2671096.4 | J20: =J18+J19 -> 2671644.7 | K20: =K18+K19 -> 2672193.2 | L20: =L18+L19 -> 2672741.8 | M20: =M18+M19 -> 2673290.4 | ... R20: =R18+R19 -> 2676035.6 | S20: =SUM(F20:R20) -> 1.070762e+08
C22: NET CASHFLOW | F22: =F15-F20 -> -75000000 | G22: =G15-G20 -> 11230000 | H22: =H15-H20 -> 6229451.9 | I22: =I15-I20 -> 6228903.6 | J22: =J15-J20 -> 6228355.3 | K22: =K15-K20 -> 6227806.8 | L22: =L15-L20 -> 6227258.2 | M22: =M15-M20 -> 6226709.6 | ... R22: =R15-R20 -> 6223964.4 | S22: =SUM(F22:R22) -> 4723798.9
C23: Cumulative | F23: =F22 -> -75000000 | G23: =F23+G22 -> -63770000 | H23: =G23+H22 -> -57540548 | I23: =H23+I22 -> -51311644 | J23: =I23+J22 -> -45083289 | K23: =J23+K22 -> -38855482 | L23: =K23+L22 -> -32628224 | M23: =L23+M22 -> -26401515 | N23: =M23+N22 -> -20175354 | ... R23: =Q23+R22 -> 4723798.9
C26: DECISION METRICS (output ke Menu)
C27: NPV (Net Present Value) | N27: =XNPV($L$5,F22:R22,F9:R9) -> 1044579.8 | Q27: Rumus: XNPV(WACC_annual, NetCF, Dates) — wajib > 0
C28: XIRR (Annualized IRR) | N28: =IFERROR(XIRR(F22:R22,F9:R9,0.1),0) -> 0.12773048 | Q28: Rumus: XIRR(NetCF, Dates) — annualized, wajib > WACC
C29: BCR / PI (Profitability Index) | N29: =IFERROR(XNPV($L$5,G15:R15,G9:R9)/ABS(F19),0) -> 1.4316323 | Q29: Rumus: PV(Inflows M1-M12) / |CAPEX|. Threshold Min 1.08, Mandatory 1.23
C30: Payback Period (bulan) | N30: =IFERROR(MATCH(TRUE(),G23:R23>=0,0),0) -> 0 | Q30: Bulan pertama cumulative CF ≥ 0. NA = tidak balik modal dalam 12 bulan.
C31: Simple ROI (selama kontrak) | N31: =IFERROR(SUM(G22:R22)/ABS(F19),0) -> 1.062984 | Q31: Rumus: Net Inflow / |CAPEX|. Simple metric tanpa diskonto.
C34: CATATAN VERIFIKATOR
C35: 1. XIRR butuh setidaknya 1 cashflow positif & 1 negatif. Kalau ada error error NUM, cek apakah CAPEX (Month 0) negatif & ada Net Inflow positif Month 1+.
C36: 2. XIRR di template ini menggunakan WACC ANNUAL (06_Asumsi!D5) untuk konsistensi dengan IRR multi-year. Hasilnya = annualized rate of return.
C37: 3. XNPV menggunakan dates yang exact, jadi result sedikit berbeda vs NPV biasa (yang assume periode equal). XNPV lebih akurat.
C38: 4. Untuk kontrak 1-tahun: Payback Period biasanya MUSTAHIL kalau CAPEX > Total Net Inflow 12 bulan. Cek kewajaran pricing.
C39: 5. BCR/PI menggunakan PV dari inflow saja vs CAPEX. Threshold per Memo DirKeu: Min 1.08, Mandatory 1.23.
C40: 6. Bulan setelah durasi kontrak otomatis di-zero-kan via Active Flag (row 10). Tidak perlu manual.

Sheet 08_Ex_Summary
B2: EXECUTIVE SUMMARY
B3: KKF Proyek Investasi 1-Tahun — siap untuk approval
B5: ← Kembali ke Menu
B7: A. IDENTITAS PROYEK
B8: • | C8: Nama Project | D8: ='01_Menu'!C6 -> (Isi nama proyek) | E8: │ | F8: Disetujui Manager | G8: ='01_Menu'!C14 -> (Nama Manager)
B9: • | C9: Nama Pelanggan | D9: ='01_Menu'!C7 -> (Isi nama pelanggan) | E9: │ | F9: Disetujui GM | G9: ='01_Menu'!C15 -> (Nama GM)
B10: • | C10: Nomor Kontrak / BAKBB | D10: ='01_Menu'!C8 -> 0 | E10: │ | F10: Disiapkan Solution Architect | G10: ='01_Menu'!C13 -> Solar
B11: • | C11: Tanggal Mulai Layanan | D11: ='01_Menu'!C9 -> 46174 | E11: │ | F11: PIC Sales | G11: ='01_Menu'!C12 -> (Nama Sales)
B12: • | C12: Durasi Kontrak | D12: ='01_Menu'!C10&" bulan" -> 12 bulan | E12: │ | F12: Tanggal KKF | G12: =TEXT(TODAY(),"dd-mmm-yyyy") -> 25-May-2026
B13: • | C13: Tanggal Akhir Layanan | D13: ='01_Menu'!C11 -> 46539 | E13: │ | F13: Versi Template | G13: "v01 (1-Tahun)"
B15: B. RINGKASAN INVESTASI & PENDAPATAN
B16: • | C16: Total CAPEX (Investasi) | D16: ='03_CAPEX'!D20 -> 75000000 | E16: Rp
B17: • | C17: Total OTC | D17: ='05_Pendapatan'!I20 -> 5000000 | E17: Rp
B18: • | C18: Sewa per bulan (gross) | D18: ='05_Pendapatan'!J20 -> 8900000 | E18: Rp/bulan
B19: • | C19: OPEX rata-rata per bulan | D19: =AVERAGE('04_OPEX_Bulanan'!F15:Q15) -> 2673016.8 | E19: Rp/bulan
B20: • | C20: Total Pendapatan selama kontrak | D20: ='07_Cashflow_Bulanan'!S14 -> 5000000 | E20: Rp
B21: • | C21: Total OPEX selama kontrak | D21: ='07_Cashflow_Bulanan'!S19 -> 75000000 | E21: Rp
B22: • | C22: Net Cash Inflow Operasional | D22: ='07_Cashflow_Bulanan'!S22-(-'07_Cashflow_Bulanan'!F22) -> -70276201 | E22: Rp
B24: C. KPI KELAYAKAN
C25: Metric | D25: Nilai | F25: Threshold | G25: Status
C26: NPV | D26: ='07_Cashflow_Bulanan'!N27 -> 1044579.8 | F26: > 0 | G26: =IF(ISNUMBER(D26),IF(D26>0,"LAYAK","TIDAK LAYAK"),"—") -> LAYAK
C27: XIRR | D27: ='07_Cashflow_Bulanan'!N28 -> 0.12773048 | F27: > WACC | G27: =IF(ISNUMBER(D27),IF(D27>'06_Asumsi'!D5,"LAYAK","TIDAK LAYAK"),"—") -> LAYAK
C28: BCR / PI | D28: ='07_Cashflow_Bulanan'!N29 -> 1.4316323 | F28: ≥ 1.23 | G28: =IF(ISNUMBER(D28),IF(D28>='06_Asumsi'!D8,"LAYAK",IF(D28>='06_Asumsi'!D7,"JUSTIFIKASI","TIDAK LAYAK")),"—") -> LAYAK
C29: Payback Period | D29: ='07_Cashflow_Bulanan'!N30 -> 0 | F29: < Durasi | G29: =IF(ISNUMBER(D29),IF(AND(D29>0,D29<'01_Menu'!C10),"LAYAK","WASPADA"),"—") -> WASPADA
C30: Simple ROI | D30: ='07_Cashflow_Bulanan'!N31 -> 1.062984 | F30: > 0% | G30: =IF(ISNUMBER(D30),IF(D30>0,"PROFIT","RUGI"),"—") -> PROFIT
B32: D. KESIMPULAN & REKOMENDASI
B33: ='01_Menu'!B44 -> ✓ INVESTASI LAYAK — Semua kriteria (NPV>0, XIRR>WACC, BCR≥1.23 Mandatory, Payback<durasi) terpenuhi. Lanjutkan ke approval.
B35: E. TANDA TANGAN
C37: Disiapkan oleh, | E37: Disetujui oleh, | G37: Mengetahui,
C38: Solution Architect | E38: Manager Pemasaran & Penjualan | G38: Senior Regional Manager
C42: ='01_Menu'!C13 -> Solar | E42: ='01_Menu'!C14 -> (Nama Manager) | G42: ='01_Menu'!C15 -> (Nama GM)
